Workbook
Name ____________________Tax1: #REF!
Name ___________________Tax1: #REF!
Name __________________Tax1: #REF!
Name _________________Tax1: #REF!
Name _________________Tax1: #REF!
Name _________________Tax1: #REF!
Name ________________Tax1: #REF!
Name ________________Tax1: #REF!
Name ________________Tax1: #REF!
Name _______________A99999: #REF!
Name _______________C99999: #REF!
Name _______________Tax1: #REF!
Name _______________Tax1: #REF!
Name _______________Tax1: #REF!
Name ______________A99999: #REF!
Name ______________C99999: #REF!
Name ______________Tax1: #REF!
Name _____________A99999: #REF!
Name _____________C99999: #REF!
Name _____________Tax1: #REF!
Name ____________A99999: #REF!
Name ____________C99999: #REF!
Name ____________Tax1: #REF!
Name ___________A99999: #REF!
Name ___________C99999: #REF!
Name ___________Tax1: #REF!
Name __________A99999: #REF!
Name __________C99999: #REF!
Name __________Tax1: #REF!
Name _________A99999: #REF!
Name _________C99999: #REF!
Name _________Tax1: #REF!
Name ________A99999: #REF!
Name ________C99999: #REF!
Name ________Tax1: #REF!
Name _______A99999: #REF!
Name _______C99999: #REF!
Name _______Tax1: #REF!
Name ______A99999: #REF!
Name ______C99999: #REF!
Name ______Tax1: #REF!
Name _____A99999: #REF!
Name _____C99999: #REF!
Name _____Tax1: #REF!
Name ____A99999: #REF!
Name ____C99999: #REF!
Name ____Tax1: #REF!
Name ___A99999: #REF!
Name ___C99999: #REF!
Name ___Tax1: #REF!
Name __A99999: #REF!
Name __C99999: #REF!
Name __Tax1: #REF!
Name __xlnm.Print_Titles_3: ([3]L1!$A:$A,[3]L1!$1:$1)
Name _A99999: #REF!
Name _A99999: #REF!
Name _A99999: #REF!
Name _C99999: #REF!
Name _C99999: #REF!
Name _C99999: #REF!

Sheet Summary
B2: Category | C2: IFRS 16 | N2: IAS 17 | O2: Difference
C3: Right of use of asset | E3: Lease liability | I3: Impact to opening RE | J3: Amortization expenses (2023) | K3: Interest expense (2023) | L3: Rent expense (2020) | M3: Total expense (2023) | N3: Rent expense (Should have been)
C4: At initial recognition | D4: At year end | E4: At initial recognition | F4: At year end | G4: Short term at 31.12.2023 | H4: Long term at 31.12.2023
A5: A | B5: Existing contracts
B6: ='01'!I14 -> Gulf Crown Furniture | C6: ='01 (2)'!D5 -> 1386418.5 | D6: ='01 (2)'!E5 -> 1006271.5 | E6: ='01 (2)'!D6 -> 1386418.5 | F6: ='01 (2)'!E6 -> 1041108.2 | G6: =F6-H6 -> 258869.32 | H6: ='01 (2)'!H71 -> 782238.87 | J6: ='01 (2)'!E9 -> 268339.06 | K6: ='01 (2)'!E8 -> 57510.306 | M6: =SUM(J6:L6) -> 325849.36 | N6: ='01 (2)'!E10 -> 303780 | O6: =M6-N6 -> 22069.363
A8: B | B8: New contracts | C8: 0 | D8: 0 | E8: 0 | F8: 0 | G8: 0 | H8: 0 | J8: 0 | K8: 0 | M8: 0 | N8: 0 | O8: 0
A10: C | B10: IFRS 16 not applied (Exempted) | D10: 0 | E10: 0 | F10: 0 | G10: 0 | H10: 0 | J10: 0 | K10: 0 | L10: 0 | M10: 0 | N10: 0 | O10: 0
C11: =SUM(C6:C10) -> 1386418.5 | D11: =SUM(D6:D10) -> 1006271.5 | E11: =SUM(E6:E10) -> 1386418.5 | F11: =SUM(F6:F10) -> 1041108.2 | G11: =SUM(G6:G10) -> 258869.32 | H11: =SUM(H6:H10) -> 782238.87 | I11: =SUM(I6:I10) -> 0 | J11: =SUM(J6:J10) -> 268339.06 | ... O11: =SUM(O6:O10) -> 22069.363
B13: ANALYSIS ON IMPACT TO FS
C14: IFRS 16 | D14: IAS 17 | E14: Difference
B16: BALANCE SHEET
B18: Assets
B19: Right of use | C19: =D11 -> 1006271.5 | D19: 0 | E19: =C19-D19 -> 1006271.5
B20: Prepaid rent | C20: 0 | D20: 0
B22: Liabilities
B23: Lease liability | C23: =F11*-1 -> -1041108.2 | D23: =0*-1 -> 0 | E23: =C23-D23 -> -1041108.2
E24: =SUM(E19:E23) -> -34836.72
B25: Equity
B26: Retained earnings | C26: =I11 -> 0 | E26: =C26-D26 -> 0
B28: INCOME STATEMENT
B30: Expense
B31: Rent expense | C31: =L11 -> 0 | D31: =N11 -> 303780 | E31: =C31-D31 -> -303780
B32: Amortization expense | C32: =J11 -> 268339.06 | D32: 0 | E32: =C32-D32 -> 268339.06
B33: Interest expense | C33: =K11 -> 57510.306 | D33: 0 | E33: =C33-D33 -> 57510.306
C35: =SUM(C31:C34) -> 325849.36 | D35: =SUM(D31:D34) -> 303780 | E35: =SUM(E31:E34) -> 22069.363
B37: PROPOSED ENTRIES:
B39: At end of the year:
A41: 1 | B41: To reverse rent expense recorded by the company:
B43: Cash/cash in bank | C43: Dr | D43: =D31 -> 303780
B44: Rent expense | C44: Cr | D44: =D43*-1 -> -303780
A46: 2 | B46: To record recognition of ROU asset and lease liability and opening RE adjustment (if applicable):
B48: ROU asset | C48: Dr | D48: =C11 -> 1386418.5
B49: Retained earnings
B50: Lease liability | C50: Cr | D50: =SUM(E11) -> 1386418.5
A52: 3 | B52: To record depreciation of ROU asset:
B54: Depreciation expense - ROU asset | C54: Dr | D54: =C32 -> 268339.06
B55: Accumulated depreciation - ROU asset | C55: Cr | D55: =D54*-1 -> -268339.06
A57: 4 | B57: To record interest expense and payment of lease liability:
B59: Lease liability | C59: Dr | D59: =D62-D61-D60 -> 246269.69 | E59: Liability repayment
B60: Rent expense | C60: Dr | D60: =L11 -> 0 | E60: As per IAS 17
...

Sheet 01
B2: Summary
D4: At initial application | E4: At year end
B5: Right-of-use asset | D5: =K43 -> 2146434.1 | E5: =K55 -> 1287860.4 | F5: =H55-H64 -> 647576.85
B6: Lease liability | D6: =H43 -> 2146434.1 | E6: =H55 -> 1319846.5
B8: Interest expense for the year | E8: =SUM(I44:I55) -> 84752.469
B9: Depreciation expense for the year | E9: =SUM(L44:L55) -> 858573.62
B10: Rent expense (IAS 17) | E10: =SUM(O44:O55) -> 911340
B12: A. Input data based on the contracts
B14: Description | I14: Gulf Crown Furniture
B15: Lessee:
B16: Lessor:
B17: Leased asset:
B18: Lease period | H18: From | I18: 44774
H19: To | I19: 46660
B20: Lessee's incremental borrowing rate at initial application date(p.a.) | I20: 0.05
B21: Remaining lease term | H21: Remaining months | I21: 30
B25: B. Calculate right-of-use asset and lease liability as at initial application date (1 January 2020). Populate table below.
B27: Fixed lease payments (discounted) | F27: =F75 -> 2146434.1 | H27: Lease liability | L27: =F37 -> 2146434.1
B29: Variable payments (discounted) | E29: (+) | H29: Initial direct costs | K29: (+) | L29: 0
B31: Residual value guarantee (discounted) | E31: (+) | H31: Cost of removal and restoring | K31: (+)
B33: Exercise price of purchase option (discounted) | E33: (+) | H33: Payments made prior to commencement | K33: (+)
B35: Termination penalties (discounted) | E35: (+) | H35: Lease incentives received | K35: (-)
B37: LEASE LIABILITY AT 1 OCTOBER 2022 | F37: =F27+F29+F31+F33+F35 -> 2146434.1 | H37: RIGHT-OF-USE ASSET AT 1 OCTOBER 2022 | L37: =L27+L29+L31+L33-L35 -> 2146434.1
H39: MONTHLY DEPRECIATION | L39: =L37/I21 -> 71547.802
O40: IAS 17
B41: Year | C41: Number | D41: Fixed lease payment (nominal) | E41: Interest rate | F41: Net present value | H41: Lease liability at period end | I41: Interest expense for the period | K41: Right-of-use asset at period end | L41: Depreciation expense for the period | M41: Total expense for the period | O41: Rent expense for the mont | P41: Prepaid asset
B42: A | C42: B | D42: C | E42: D | F42: E | H42: F | I42: G | K42: H | L42: I | M42: J
H43: =F37 -> 2146434.1 | K43: =L37 -> 2146434.1
B44: 44835 | C44: 1 | D44: 75945 | E44: =$I$20/12 -> 0.0041666667 | F44: =D44/(1+E44)^(C44-1) -> 75945 | H44: =H43+I44-D44 -> 2079116.1 | I44: =(H43-D44)*E44 -> 8627.0377 | K44: =K43-L44 -> 2074886.2 | L44: =$L$39 -> 71547.802 | M44: =I44+L44 -> 80174.839 | O44: =D44 -> 75945
B45: 44927 | C45: 2 | D45: 75945 | E45: =$I$20/12 -> 0.0041666667 | F45: =D45/(1+E45)^(C45-1) -> 75629.876 | H45: =H44+I45-D45 -> 2011517.6 | I45: =(H44-D45)*E45 -> 8346.5462 | K45: =K44-L45 -> 2003338.4 | L45: =$L$39 -> 71547.802 | M45: =I45+L45 -> 79894.348 | O45: =D45 -> 75945
B46: 45017 | C46: 3 | D46: 75945 | E46: =$I$20/12 -> 0.0041666667 | F46: =D46/(1+E46)^(C46-1) -> 75316.059 | H46: =H45+I46-D46 -> 1943637.5 | I46: =(H45-D46)*E46 -> 8064.886 | K46: =K45-L46 -> 1931790.6 | L46: =$L$39 -> 71547.802 | M46: =I46+L46 -> 79612.688 | O46: =D46 -> 75945
B47: 45108 | C47: 4 | D47: 75945 | E47: =$I$20/12 -> 0.0041666667 | F47: =D47/(1+E47)^(C47-1) -> 75003.544 | H47: =H46+I47-D47 -> 1875474.6 | I47: =(H46-D47)*E47 -> 7782.0522 | K47: =K46-L47 -> 1860242.8 | L47: =$L$39 -> 71547.802 | M47: =I47+L47 -> 79329.854 | O47: =D47 -> 75945
B48: 45200 | C48: 5 | D48: 75945 | E48: =$I$20/12 -> 0.0041666667 | F48: =D48/(1+E48)^(C48-1) -> 74692.326 | H48: =H47+I48-D48 -> 1807027.6 | I48: =(H47-D48)*E48 -> 7498.0399 | K48: =K47-L48 -> 1788695 | L48: =$L$39 -> 71547.802 | M48: =I48+L48 -> 79045.842 | O48: =D48 -> 75945
B49: 45292 | C49: 6 | D49: 75945 | E49: =$I$20/12 -> 0.0041666667 | F49: =D49/(1+E49)^(C49-1) -> 74382.399 | H49: =H48+I49-D49 -> 1738295.5 | I49: =(H48-D49)*E49 -> 7212.8442 | K49: =K48-L49 -> 1717147.2 | L49: =$L$39 -> 71547.802 | M49: =I49+L49 -> 78760.646 | O49: =D49 -> 75945
B50: 45383 | C50: 7 | D50: 75945 | E50: =$I$20/12 -> 0.0041666667 | F50: =D50/(1+E50)^(C50-1) -> 74073.758 | H50: =H49+I50-D50 -> 1669276.9 | I50: =(H49-D50)*E50 -> 6926.4602 | K50: =K49-L50 -> 1645599.4 | L50: =$L$39 -> 71547.802 | M50: =I50+L50 -> 78474.262 | O50: =D50 -> 75945
B51: 45474 | C51: 8 | D51: 75945 | E51: =$I$20/12 -> 0.0041666667 | F51: =D51/(1+E51)^(C51-1) -> 73766.399 | H51: =H50+I51-D51 -> 1599970.8 | I51: =(H50-D51)*E51 -> 6638.883 | K51: =K50-L51 -> 1574051.6 | L51: =$L$39 -> 71547.802 | M51: =I51+L51 -> 78186.685 | O51: =D51 -> 75945
B52: 45566 | C52: 9 | D52: 75945 | E52: =$I$20/12 -> 0.0041666667 | F52: =D52/(1+E52)^(C52-1) -> 73460.314 | H52: =H51+I52-D52 -> 1530375.9 | I52: =(H51-D52)*E52 -> 6350.1075 | K52: =K51-L52 -> 1502503.8 | L52: =$L$39 -> 71547.802 | M52: =I52+L52 -> 77897.909 | O52: =D52 -> 75945
B53: 45658 | C53: 10 | D53: 75945 | E53: =$I$20/12 -> 0.0041666667 | F53: =D53/(1+E53)^(C53-1) -> 73155.499 | H53: =H52+I53-D53 -> 1460491 | I53: =(H52-D53)*E53 -> 6060.1288 | K53: =K52-L53 -> 1430956 | L53: =$L$39 -> 71547.802 | M53: =I53+L53 -> 77607.931 | O53: =D53 -> 75945
B54: 45748 | C54: 11 | D54: 75945 | E54: =$I$20/12 -> 0.0041666667 | F54: =D54/(1+E54)^(C54-1) -> 72851.949 | H54: =H53+I54-D54 -> 1390315 | I54: =(H53-D54)*E54 -> 5768.9418 | K54: =K53-L54 -> 1359408.2 | L54: =$L$39 -> 71547.802 | M54: =I54+L54 -> 77316.744 | O54: =D54 -> 75945
B55: 45839 | C55: 12 | D55: 75945 | E55: =$I$20/12 -> 0.0041666667 | F55: =D55/(1+E55)^(C55-1) -> 72549.659 | H55: =H54+I55-D55 -> 1319846.5 | I55: =(H54-D55)*E55 -> 5476.5416 | K55: =K54-L55 -> 1287860.4 | L55: =$L$39 -> 71547.802 | M55: =I55+L55 -> 77024.343 | O55: =D55 -> 75945
...

Sheet 01 (2)
B2: Summary
D4: At initial application | E4: At year end | P4: ROU - ASSETS | Q4: =D5 -> 1386418.5
B5: Right-of-use asset | D5: =K42 -> 1386418.5 | E5: =K59 -> 1006271.5 | P5: ROU - LIABILITY | R5: =D5 -> 1386418.5
B6: Lease liability | D6: =H42 -> 1386418.5 | E6: =H59 -> 1041108.2
P7: AMORT | Q7: =E9 -> 268339.06
B8: Interest expense for the year | E8: =SUM(I48:I59) -> 57510.306 | P8: ACC. AMORTIZATION | R8: =E9 -> 268339.06
B9: Depreciation expense for the year | E9: =SUM(L48:L59) -> 268339.06
B10: Rent expense (IAS 17) | E10: =SUM(D48:D59) -> 303780 | P10: LEASE LIABILITY | Q10: =R12-Q11 -> 246269.69
P11: INT EXP | Q11: =E8 -> 57510.306
B12: A. Input data based on the contracts | P12: RENT | R12: =E10 -> 303780
T13: =R12-Q14 -> 278465
B14: Description | I14: Gulf Crown Furniture | P14: RENT | Q14: 25315
B15: Lessee: | P15: OTHER INCOME | R15: 25315
B16: Lessor:
B17: Leased asset:
B18: Lease period | H18: From | I18: 44774
H19: To | I19: 46660
B20: Lessee's incremental borrowing rate at initial application date(p.a.) | I20: 0.05
B21: Remaining lease term | H21: Remaining months | I21: 62
B23: B. Calculate right-of-use asset and lease liability as at initial application date (1 January 2020). Populate table below.
B25: Fixed lease payments (discounted) | F25: =F105 -> 1386418.5 | H25: Lease liability | L25: =F35 -> 1386418.5
B27: Variable payments (discounted) | E27: (+) | H27: Initial direct costs | K27: (+) | L27: 0
B29: Residual value guarantee (discounted) | E29: (+) | H29: Cost of removal and restoring | K29: (+)
B31: Exercise price of purchase option (discounted) | E31: (+) | H31: Payments made prior to commencement | K31: (+)
B33: Termination penalties (discounted) | E33: (+) | H33: Lease incentives received | K33: (-)
B35: LEASE LIABILITY AT 1 AUG 2022 | F35: =F25+F27+F29+F31+F33 -> 1386418.5 | H35: RIGHT-OF-USE ASSET AT 1 AUG 2022 | L35: =L25+L27+L29+L31-L33 -> 1386418.5
H37: MONTHLY DEPRECIATION | L37: =L35/I21 -> 22361.588
B40: Year | C40: Number | D40: Fixed lease payment (nominal) | E40: Interest rate | F40: Net present value | H40: Lease liability at period end | I40: Interest expense for the period | K40: Right-of-use asset at period end | L40: Depreciation expense for the period | M40: Total expense for the period
B41: A | C41: B | D41: C | E41: D | F41: E | H41: F | I41: G | K41: H | L41: I | M41: J
H42: =F35 -> 1386418.5 | K42: =L35 -> 1386418.5
B43: 44774 | C43: 1 | D43: 25315 | E43: =$I$20/12 -> 0.0041666667 | F43: =D43/(1+E43)^(C43-1) -> 25315 | H43: =H42+I43-D43 -> 1366774.7 | I43: =(H42-D43)*E43 -> 5671.2644 | K43: =K42-L43 -> 1364056.9 | L43: =$L$37 -> 22361.588 | M43: =I43+L43 -> 28032.853
B44: 44805 | C44: 2 | D44: 25315 | E44: =$I$20/12 -> 0.0041666667 | F44: =D44/(1+E44)^(C44-1) -> 25209.959 | H44: =H43+I44-D44 -> 1347049.1 | I44: =(H43-D44)*E44 -> 5589.4155 | K44: =K43-L44 -> 1341695.3 | L44: =$L$37 -> 22361.588 | M44: =I44+L44 -> 27951.004
B45: 44835 | C45: 3 | D45: 25315 | E45: =$I$20/12 -> 0.0041666667 | F45: =D45/(1+E45)^(C45-1) -> 25105.353 | H45: =H44+I45-D45 -> 1327241.4 | I45: =(H44-D45)*E45 -> 5507.2256 | K45: =K44-L45 -> 1319333.7 | L45: =$L$37 -> 22361.588 | M45: =I45+L45 -> 27868.814
B46: 44866 | C46: 4 | D46: 25315 | E46: =$I$20/12 -> 0.0041666667 | F46: =D46/(1+E46)^(C46-1) -> 25001.181 | H46: =H45+I46-D46 -> 1307351.1 | I46: =(H45-D46)*E46 -> 5424.6932 | K46: =K45-L46 -> 1296972.1 | L46: =$L$37 -> 22361.588 | M46: =I46+L46 -> 27786.281
B47: 44896 | C47: 5 | D47: 25315 | E47: =$I$20/12 -> 0.0041666667 | F47: =D47/(1+E47)^(C47-1) -> 24897.442 | H47: =H46+I47-D47 -> 1287377.9 | I47: =(H46-D47)*E47 -> 5341.8169 | K47: =K46-L47 -> 1274610.5 | L47: =$L$37 -> 22361.588 | M47: =I47+L47 -> 27703.405
B48: 44927 | C48: 6 | D48: 25315 | E48: =$I$20/12 -> 0.0041666667 | F48: =D48/(1+E48)^(C48-1) -> 24794.133 | H48: =H47+I48-D48 -> 1267321.5 | I48: =(H47-D48)*E48 -> 5258.5953 | K48: =K47-L48 -> 1252248.9 | L48: =$L$37 -> 22361.588 | M48: =I48+L48 -> 27620.184
B49: 44958 | C49: 7 | D49: 25315 | E49: =$I$20/12 -> 0.0041666667 | F49: =D49/(1+E49)^(C49-1) -> 24691.253 | H49: =H48+I49-D49 -> 1247181.5 | I49: =(H48-D49)*E49 -> 5175.027 | K49: =K48-L49 -> 1229887.3 | L49: =$L$37 -> 22361.588 | M49: =I49+L49 -> 27536.615
B50: 44986 | C50: 8 | D50: 25315 | E50: =$I$20/12 -> 0.0041666667 | F50: =D50/(1+E50)^(C50-1) -> 24588.8 | H50: =H49+I50-D50 -> 1226957.6 | I50: =(H49-D50)*E50 -> 5091.1104 | K50: =K49-L50 -> 1207525.8 | L50: =$L$37 -> 22361.588 | M50: =I50+L50 -> 27452.699
B51: 45017 | C51: 9 | D51: 25315 | E51: =$I$20/12 -> 0.0041666667 | F51: =D51/(1+E51)^(C51-1) -> 24486.771 | H51: =H50+I51-D51 -> 1206649.5 | I51: =(H50-D51)*E51 -> 5006.8442 | K51: =K50-L51 -> 1185164.2 | L51: =$L$37 -> 22361.588 | M51: =I51+L51 -> 27368.432
B52: 45047 | C52: 10 | D52: 25315 | E52: =$I$20/12 -> 0.0041666667 | F52: =D52/(1+E52)^(C52-1) -> 24385.166 | H52: =H51+I52-D52 -> 1186256.7 | I52: =(H51-D52)*E52 -> 4922.2269 | K52: =K51-L52 -> 1162802.6 | L52: =$L$37 -> 22361.588 | M52: =I52+L52 -> 27283.815
...

Sheet JE
A1: Journal Entries to be passed for IFRS 16 calculation
A3: # | B3: Description | C3: Dr. | D3: Cr.
A5: 1 | B5: Finance cost | C5: 57510.306
B6: Lease liability | C6: 246269.69
B7: Rental expenses | D7: =C5+C6 -> 303780
B8: (Removal of rental expense)
A10: 2 | B10: Amortization - right of use asset | C10: =Summary!D54 -> 268339.06
B11: Accumulated amortization - right of use asset | D11: =C10 -> 268339.06
B12: (Amortization for right of use assets)
